<?xml version="1.0"?>
<sdf version="1.6">
  <world name="default">
    <plugin name="WorldController" filename="libWorldController.so"/>

    <gui>
      <plugin name="score" filename="libGameScoreManager.so"/>
      <plugin name="sample" filename="libgui_example_time_widget.so"/>
    </gui>
    
    <light name='sun' type='directional'>
      <pose frame=''>0 0 9 0 -0 0</pose>
      <diffuse>0.8 0.8 0.8 1</diffuse>
      <specular>0.2 0.2 0.2 1</specular>
      <attenuation>
        <range>1000</range>
        <constant>0.9</constant>
        <linear>0.01</linear>
        <quadratic>0.001</quadratic>
      </attenuation>
      <direction>-0 0 -1</direction>
    </light>
    
    <model name='building'>
        <static>1</static>
        <link name='floor'>
            <collision name='floor_Collision'>
                <geometry>
                    <box>
                        <size>24.01 24 0.01</size>
                    </box>
                </geometry>
                <pose frame=''>0 0 0 0 -0 0</pose>
                <max_contacts>10</max_contacts>
                <surface>
                  <friction>
                    <ode>
                      <mu>100</mu>
                      <mu2>50</mu2>
                    </ode>
                    <torsional>
                      <ode/>
                    </torsional>
                  </friction>
                  <contact>
                    <ode/>
                  </contact>
                  <bounce/>
                </surface>
            </collision>
            <visual name='floor_Visual'>
                <pose frame=''>0 0 0 0 -0 0</pose>
                <geometry>
                    <box>
                        <normal>0 0 1</normal>
                        <size>24.01 24 0.01</size>
                    </box>
                </geometry>
                <material>
                    <script>
                        <uri>file://Gym/IARC_material.material</uri>
                        <name>Gazebo/IARC2</name>
                    </script>
                    <ambient>1 0.764706 0.305882 1</ambient>
                </material>
                <meta>
                    <layer>0</layer>
                </meta>
            </visual>
            <pose frame=''>0 0.005 0 0 -0 1.5708</pose>
            <self_collide>0</self_collide>
            <enable_wind>0</enable_wind>
            <kinematic>0</kinematic>
        </link>
    </model>

    <plugin filename="libSimEventsPlugin.so" name="out_of_bounds_event">
        <region>
          <name>left_boundary</name>
          <volume>
            <min>-10 -12 0</min>
            <max>-12 12 1000</max>
          </volume>
        </region>

        <region>
          <name>right_boundary</name>
          <volume>
            <min>10 -12 0</min>
            <max>12 12 1000</max>
          </volume>
        </region>

        <!-- red line -->

        <region>
          <name>back_boundary</name>
          <volume>
            <min>-10 -10 0</min>
            <max>10 -12 1000</max>
          </volume>
        </region>

        <!-- green line -->
        
        <region>
          <name>front_boundary</name>
          <volume>
            <min>-10 10 0</min>
            <max>10 12 1000</max>
          </volume>
        </region>

        <event>
          <name>left_boundary_event</name>
          <type>occupied</type>
          <region>left_boundary</region>
          <topic>~/out_of_bounds</topic>
          <msg_data>left</msg_data>
        </event>

        <event>
          <name>right_boundary_event</name>
          <type>occupied</type>
          <region>right_boundary</region>
          <topic>~/out_of_bounds</topic>
          <msg_data>right</msg_data>
        </event>

        <event>
          <name>back_boundary_event</name>
          <type>occupied</type>
          <region>back_boundary</region>
          <topic>~/out_of_bounds</topic>
          <msg_data>back</msg_data>
        </event>

        <event>
          <name>front_boundary_event</name>
          <type>occupied</type>
          <region>front_boundary</region>
          <topic>~/out_of_bounds</topic>
          <msg_data>front</msg_data>
        </event>

        <event>
          <name>back_boundary_event</name>
          <type>occupied</type>
          <region>back_boundary</region>
          <topic>~/out_of_bounds</topic>
          <msg_data>0</msg_data>
        </event>
    </plugin>

   <model name='create1'>
      <link name='base'>
        <inertial>
          <inertia>
            <ixx>0.001</ixx>
            <ixy>0</ixy>
            <ixz>0</ixz>
            <iyy>0.001</iyy>
            <iyz>0</iyz>
            <izz>0.001</izz>
          </inertia>
          <mass>3.5</mass>
        </inertial>
        <collision name='base_collision'>
          <pose frame=''>0 0 0.0478 0 -0 0</pose>
          <geometry>
            <cylinder>
              <radius>0.16495</radius>
              <length>0.08294</length>
            </cylinder>
          </geometry>
          <max_contacts>10</max_contacts>
          <surface>
            <contact>
              <ode/>
            </contact>
            <bounce/>
            <friction>
              <torsional>
                <ode/>
              </torsional>
              <ode/>
            </friction>
          </surface>
        </collision>
        <collision name='bumper_collision'>
          <pose frame=''>0.01 0 0.0478 0 -0 0</pose>
          <geometry>
            <cylinder>
              <radius>0.16495</radius>
              <length>0.061163</length>
            </cylinder>
          </geometry>
          <max_contacts>10</max_contacts>
          <surface>
            <contact>
              <ode/>
            </contact>
            <bounce/>
            <friction>
              <torsional>
                <ode/>
              </torsional>
              <ode/>
            </friction>
          </surface>
        </collision>
        <sensor name='my_contact' type='contact'>
          <contact>
            <collision>bumper_collision</collision>
          </contact>
        </sensor>
        <visual name='base_visual'>
          <pose frame=''>0 0 0.0478 0 -0 0</pose>
          <geometry>
            <mesh>
              <uri>file://Assets/meshes/create_body_red.dae</uri>
              <scale>1 1 1</scale>
            </mesh>
          </geometry>
        </visual>
        <collision name='top_flap_collision'>
          <pose frame=''>0 0 0.1 0 -0 0</pose>
          <geometry>
            <box>
              <size> 0.1 0.1 0.01 </size>
            </box>
          </geometry>
          <max_contacts>10</max_contacts>
          <surface>
            <contact>
              <ode/>
            </contact>
            <bounce/>
            <friction>
              <torsional>
                <ode/>
              </torsional>
              <ode/>
            </friction>
          </surface>
        </collision>
        <sensor name='my_contact_2' type='contact'>
          <contact>
            <collision>top_flap_collision</collision>
          </contact>
        </sensor>

        <collision name='front_wheel_collision'>
          <pose frame=''>0.13 0 0.017 -0 1.5707 1.5707</pose>
          <geometry>
            <sphere>
              <radius>0.018</radius>
            </sphere>
          </geometry>
          <surface>
            <friction>
              <ode>
                <mu>0</mu>
                <mu2>0</mu2>
                <fdir1>0 0 0</fdir1>
                <slip1>0</slip1>
                <slip2>0</slip2>
              </ode>
              <torsional>
                <ode/>
              </torsional>
            </friction>
            <contact>
              <ode/>
            </contact>
            <bounce/>
          </surface>
          <max_contacts>10</max_contacts>
        </collision>

        <collision name='rear_wheel_collision'>
          <pose frame=''>-0.13 0 0.017 -0 1.5707 1.5707</pose>
          <geometry>
            <sphere>
              <radius>0.015</radius>
            </sphere>
          </geometry>
          <surface>
            <friction>
              <ode>
                <mu>0</mu>
                <mu2>0</mu2>
                <fdir1>0 0 0</fdir1>
                <slip1>0</slip1>
                <slip2>0</slip2>
              </ode>
              <torsional>
                <ode/>
              </torsional>
            </friction>
            <contact>
              <ode/>
            </contact>
            <bounce/>
          </surface>
          <max_contacts>10</max_contacts>
        </collision>

        <self_collide>0</self_collide>
        <enable_wind>0</enable_wind>
        <kinematic>0</kinematic>
      </link>
      <link name='left_wheel'>
        <pose frame=''>0 0.1175 0.032 0 -0 0</pose>
        <inertial>
          <inertia>
            <ixx>0.001</ixx>
            <ixy>0</ixy>
            <ixz>0</ixz>
            <iyy>0.001</iyy>
            <iyz>0</iyz>
            <izz>0.001</izz>
          </inertia>
          <mass>0.01</mass>
        </inertial>
        <collision name='collision'>
          <pose frame=''>0 0 0 -0 1.5707 1.5707</pose>
          <geometry>
            <cylinder>
              <radius>0.033</radius>
              <length>0.023</length>
            </cylinder>
          </geometry>
          <surface>
            <friction>
              <ode>
                <mu>10</mu>
                <mu2>10</mu2>
                <fdir1>0 0 0</fdir1>
                <slip1>0</slip1>
                <slip2>0</slip2>
              </ode>
              <torsional>
                <ode/>
              </torsional>
            </friction>
            <contact>
              <ode/>
            </contact>
            <bounce/>
          </surface>
          <max_contacts>10</max_contacts>
        </collision>

        <self_collide>0</self_collide>
        <enable_wind>0</enable_wind>
        <kinematic>0</kinematic>
      </link>
      <link name='right_wheel'>
        <pose frame=''>0 -0.1175 0.032 0 -0 0</pose>
        <inertial>
          <inertia>
            <ixx>0.001</ixx>
            <ixy>0</ixy>
            <ixz>0</ixz>
            <iyy>0.001</iyy>
            <iyz>0</iyz>
            <izz>0.001</izz>
          </inertia>
          <mass>0.01</mass>
        </inertial>
        <collision name='collision'>
          <pose frame=''>0 0 0 -0 1.5707 1.5707</pose>
          <geometry>
            <cylinder>
              <radius>0.033</radius>
              <length>0.023</length>
            </cylinder>
          </geometry>
          <surface>
            <friction>
              <ode>
                <mu>10</mu>
                <mu2>10</mu2>
                <fdir1>0 0 0</fdir1>
                <slip1>0</slip1>
                <slip2>0</slip2>
              </ode>
              <torsional>
                <ode/>
              </torsional>
            </friction>
            <contact>
              <ode/>
            </contact>
            <bounce/>
          </surface>
          <max_contacts>10</max_contacts>
        </collision>

        <self_collide>0</self_collide>
        <enable_wind>0</enable_wind>
        <kinematic>0</kinematic>
      </link>
      <joint name='left_wheel' type='revolute'>
        <parent>base</parent>
        <child>left_wheel</child>
        <axis>
          <xyz>0 1 0</xyz>
          <use_parent_model_frame>1</use_parent_model_frame>
          <limit>
            <lower>-1e+16</lower>
            <upper>1e+16</upper>
          </limit>
          <dynamics>
            <spring_reference>0</spring_reference>
            <spring_stiffness>0</spring_stiffness>
          </dynamics>
        </axis>
      </joint>
      <joint name='right_wheel' type='revolute'>
        <parent>base</parent>
        <child>right_wheel</child>
        <axis>
          <xyz>0 1 0</xyz>
          <use_parent_model_frame>1</use_parent_model_frame>
          <limit>
            <lower>-1e+16</lower>
            <upper>1e+16</upper>
          </limit>
          <dynamics>
            <spring_reference>0</spring_reference>
            <spring_stiffness>0</spring_stiffness>
          </dynamics>
        </axis>
      </joint>
      <pose frame=''>1 0 0.01 0 -0 0</pose>
      <plugin name="model_push" filename="libmodel_push.so"/>
    </model>

    <model name='create2'>
      <link name='base'>
        <inertial>
          <inertia>
            <ixx>0.001</ixx>
            <ixy>0</ixy>
            <ixz>0</ixz>
            <iyy>0.001</iyy>
            <iyz>0</iyz>
            <izz>0.001</izz>
          </inertia>
          <mass>3.5</mass>
        </inertial>
        <collision name='base_collision'>
          <pose frame=''>0 0 0.0478 0 -0 0</pose>
          <geometry>
            <cylinder>
              <radius>0.16495</radius>
              <length>0.08294</length>
            </cylinder>
          </geometry>
          <max_contacts>10</max_contacts>
          <surface>
            <contact>
              <ode/>
            </contact>
            <bounce/>
            <friction>
              <torsional>
                <ode/>
              </torsional>
              <ode/>
            </friction>
          </surface>
        </collision>
        <collision name='bumper_collision'>
          <pose frame=''>0.01 0 0.0478 0 -0 0</pose>
          <geometry>
            <cylinder>
              <radius>0.16495</radius>
              <length>0.061163</length>
            </cylinder>
          </geometry>
          <max_contacts>10</max_contacts>
          <surface>
            <contact>
              <ode/>
            </contact>
            <bounce/>
            <friction>
              <torsional>
                <ode/>
              </torsional>
              <ode/>
            </friction>
          </surface>
        </collision>
        <sensor name='my_contact' type='contact'>
          <contact>
            <collision>bumper_collision</collision>
          </contact>
        </sensor>
        <visual name='base_visual'>
          <pose frame=''>0 0 0.0478 0 -0 0</pose>
          <geometry>
            <mesh>
              <uri>file://Assets/meshes/create_body_green.dae</uri>
              <scale>1 1 1</scale>
            </mesh>
          </geometry>
        </visual>
        <collision name='top_flap_collision'>
          <pose frame=''>0 0 0.1 0 -0 0</pose>
          <geometry>
            <box>
              <size> 0.1 0.1 0.01 </size>
            </box>
          </geometry>
          <max_contacts>10</max_contacts>
          <surface>
            <contact>
              <ode/>
            </contact>
            <bounce/>
            <friction>
              <torsional>
                <ode/>
              </torsional>
              <ode/>
            </friction>
          </surface>
        </collision>
        <sensor name='my_contact_2' type='contact'>
          <contact>
            <collision>top_flap_collision</collision>
          </contact>
        </sensor>

        <collision name='front_wheel_collision'>
          <pose frame=''>0.13 0 0.017 -0 1.5707 1.5707</pose>
          <geometry>
            <sphere>
              <radius>0.018</radius>
            </sphere>
          </geometry>
          <surface>
            <friction>
              <ode>
                <mu>0</mu>
                <mu2>0</mu2>
                <fdir1>0 0 0</fdir1>
                <slip1>0</slip1>
                <slip2>0</slip2>
              </ode>
              <torsional>
                <ode/>
              </torsional>
            </friction>
            <contact>
              <ode/>
            </contact>
            <bounce/>
          </surface>
          <max_contacts>10</max_contacts>
        </collision>

        <collision name='rear_wheel_collision'>
          <pose frame=''>-0.13 0 0.017 -0 1.5707 1.5707</pose>
          <geometry>
            <sphere>
              <radius>0.015</radius>
            </sphere>
          </geometry>
          <surface>
            <friction>
              <ode>
                <mu>0</mu>
                <mu2>0</mu2>
                <fdir1>0 0 0</fdir1>
                <slip1>0</slip1>
                <slip2>0</slip2>
              </ode>
              <torsional>
                <ode/>
              </torsional>
            </friction>
            <contact>
              <ode/>
            </contact>
            <bounce/>
          </surface>
          <max_contacts>10</max_contacts>
        </collision>

        <self_collide>0</self_collide>
        <enable_wind>0</enable_wind>
        <kinematic>0</kinematic>
      </link>
      <link name='left_wheel'>
        <pose frame=''>0 0.1175 0.032 0 -0 0</pose>
        <inertial>
          <inertia>
            <ixx>0.001</ixx>
            <ixy>0</ixy>
            <ixz>0</ixz>
            <iyy>0.001</iyy>
            <iyz>0</iyz>
            <izz>0.001</izz>
          </inertia>
          <mass>0.01</mass>
        </inertial>
        <collision name='collision'>
          <pose frame=''>0 0 0 -0 1.5707 1.5707</pose>
          <geometry>
            <cylinder>
              <radius>0.033</radius>
              <length>0.023</length>
            </cylinder>
          </geometry>
          <surface>
            <friction>
              <ode>
                <mu>10</mu>
                <mu2>10</mu2>
                <fdir1>0 0 0</fdir1>
                <slip1>0</slip1>
                <slip2>0</slip2>
              </ode>
              <torsional>
                <ode/>
              </torsional>
            </friction>
            <contact>
              <ode/>
            </contact>
            <bounce/>
          </surface>
          <max_contacts>10</max_contacts>
        </collision>

        <self_collide>0</self_collide>
        <enable_wind>0</enable_wind>
        <kinematic>0</kinematic>
      </link>
      <link name='right_wheel'>
        <pose frame=''>0 -0.1175 0.032 0 -0 0</pose>
        <inertial>
          <inertia>
            <ixx>0.001</ixx>
            <ixy>0</ixy>
            <ixz>0</ixz>
            <iyy>0.001</iyy>
            <iyz>0</iyz>
            <izz>0.001</izz>
          </inertia>
          <mass>0.01</mass>
        </inertial>
        <collision name='collision'>
          <pose frame=''>0 0 0 -0 1.5707 1.5707</pose>
          <geometry>
            <cylinder>
              <radius>0.033</radius>
              <length>0.023</length>
            </cylinder>
          </geometry>
          <surface>
            <friction>
              <ode>
                <mu>10</mu>
                <mu2>10</mu2>
                <fdir1>0 0 0</fdir1>
                <slip1>0</slip1>
                <slip2>0</slip2>
              </ode>
              <torsional>
                <ode/>
              </torsional>
            </friction>
            <contact>
              <ode/>
            </contact>
            <bounce/>
          </surface>
          <max_contacts>10</max_contacts>
        </collision>

        <self_collide>0</self_collide>
        <enable_wind>0</enable_wind>
        <kinematic>0</kinematic>
      </link>
      <joint name='left_wheel' type='revolute'>
        <parent>base</parent>
        <child>left_wheel</child>
        <axis>
          <xyz>0 1 0</xyz>
          <use_parent_model_frame>1</use_parent_model_frame>
          <limit>
            <lower>-1e+16</lower>
            <upper>1e+16</upper>
          </limit>
          <dynamics>
            <spring_reference>0</spring_reference>
            <spring_stiffness>0</spring_stiffness>
          </dynamics>
        </axis>
      </joint>
      <joint name='right_wheel' type='revolute'>
        <parent>base</parent>
        <child>right_wheel</child>
        <axis>
          <xyz>0 1 0</xyz>
          <use_parent_model_frame>1</use_parent_model_frame>
          <limit>
            <lower>-1e+16</lower>
            <upper>1e+16</upper>
          </limit>
          <dynamics>
            <spring_reference>0</spring_reference>
            <spring_stiffness>0</spring_stiffness>
          </dynamics>
        </axis>
      </joint>
      <pose frame=''>0.809016994 0.587785252 .01 0 -0 0.63</pose>
      <plugin name="model_push" filename="libmodel_push.so"/>
    </model>

    <model name="Sentinel">
        <include>
          <uri>model://iris_with_standoffs_demo</uri>
        </include>

        <model name='realsense_camera'>
          <plugin name='realsense_plugin' filename='libRealSensePlugin.so'/>
          <pose frame=''>0 0 .16 3.14159 1.56129 3.14159</pose>
          <link name='link'>
            <inertial>
              <mass>0.0615752</mass>
              <inertia>
                <ixx>9.108e-05</ixx>
                <ixy>0</ixy>
                <ixz>0</ixz>
                <iyy>2.51e-06</iyy>
                <iyz>0</iyz>
                <izz>8.931e-05</izz>
              </inertia>
              <pose frame=''>0 0 0 0 -0 0</pose>
            </inertial>
            <self_collide>0</self_collide>
            <enable_wind>0</enable_wind>
            <kinematic>0</kinematic>
            <gravity>1</gravity>
            <visual name='visual'>
              <geometry>
                <mesh>
                  <uri>model://realsense_camera/meshes/realsense.dae</uri>
                </mesh>
              </geometry>
            </visual>
            <collision name='collision'>
              <laser_retro>0</laser_retro>
              <max_contacts>10</max_contacts>
              <pose frame=''>0 0 0 0 -0 0</pose>
              <geometry>
                <box>
                  <size>0.0078 0.13 0.0192</size>
                </box>
              </geometry>
              <surface>
                <friction>
                  <ode>
                    <mu>1</mu>
                    <mu2>1</mu2>
                    <fdir1>0 0 0</fdir1>
                    <slip1>0</slip1>
                    <slip2>0</slip2>
                  </ode>
                  <torsional>
                    <coefficient>1</coefficient>
                    <patch_radius>0</patch_radius>
                    <surface_radius>0</surface_radius>
                    <use_patch_radius>1</use_patch_radius>
                    <ode>
                      <slip>0</slip>
                    </ode>
                  </torsional>
                </friction>
                <bounce>
                  <restitution_coefficient>0</restitution_coefficient>
                  <threshold>1e+06</threshold>
                </bounce>
                <contact>
                  <collide_without_contact>0</collide_without_contact>
                  <collide_without_contact_bitmask>1</collide_without_contact_bitmask>
                  <collide_bitmask>1</collide_bitmask>
                  <ode>
                    <soft_cfm>0</soft_cfm>
                    <soft_erp>0.2</soft_erp>
                    <kp>1e+13</kp>
                    <kd>1</kd>
                    <max_vel>0.01</max_vel>
                    <min_depth>0</min_depth>
                  </ode>
                  <bullet>
                    <split_impulse>1</split_impulse>
                    <split_impulse_penetration_threshold>-0.01</split_impulse_penetration_threshold>
                    <soft_cfm>0</soft_cfm>
                    <soft_erp>0.2</soft_erp>
                    <kp>1e+13</kp>
                    <kd>1</kd>
                  </bullet>
                </contact>
              </surface>
            </collision>
            <sensor name='color' type='camera'>
              <pose frame=''>0 -0.046 0.004 0 0 0</pose>
              <camera name='__default__'>
                <horizontal_fov>1.047</horizontal_fov>
                <image>
                  <width>640</width>
                  <height>480</height>
                  <format>RGB_INT8</format>
                </image>
                <clip>
                  <near>0.1</near>
                  <far>100</far>
                </clip>
                <noise>
                  <type>gaussian</type>
                  <mean>0</mean>
                  <stddev>0.007</stddev>
                </noise>
              </camera>
              <always_on>1</always_on>
              <update_rate>60</update_rate>
              <visualize>1</visualize>
            </sensor>
            <sensor name='ired1' type='camera'>
              <pose frame=''>0 -0.06 0.004 0 -0 0</pose>
              <camera name='__default__'>
                <horizontal_fov>1.047</horizontal_fov>
                <image>
                  <width>640</width>
                  <height>480</height>
                  <format>L_INT8</format>
                </image>
                <clip>
                  <near>0.1</near>
                  <far>100</far>
                </clip>
                <noise>
                  <type>gaussian</type>
                  <mean>0</mean>
                  <stddev>0.007</stddev>
                </noise>
              </camera>
              <always_on>1</always_on>
              <update_rate>60</update_rate>
              <visualize>0</visualize>
            </sensor>
            <sensor name='ired2' type='camera'>
              <pose frame=''>0 0.01 0.004 0 -0 0</pose>
              <camera name='__default__'>
                <horizontal_fov>1.047</horizontal_fov>
                <image>
                  <width>640</width>
                  <height>480</height>
                  <format>L_INT8</format>
                </image>
                <clip>
                  <near>0.1</near>
                  <far>100</far>
                </clip>
                <noise>
                  <type>gaussian</type>
                  <mean>0</mean>
                  <stddev>0.007</stddev>
                </noise>
              </camera>
              <always_on>1</always_on>
              <update_rate>60</update_rate>
              <visualize>0</visualize>
            </sensor>
            <sensor name='depth' type='depth'>
              <pose frame=''>0 -0.03 0.004 0 -0 0</pose>
              <camera name='__default__'>
                <horizontal_fov>1.047</horizontal_fov>
                <image>
                  <width>640</width>
                  <height>480</height>
                </image>
                <clip>
                  <near>0.1</near>
                  <far>100</far>
                </clip>
                <noise>
                  <type>gaussian</type>
                  <mean>0</mean>
                  <stddev>0.007</stddev>
                </noise>
              </camera>
              <always_on>1</always_on>
              <update_rate>60</update_rate>
              <visualize>1</visualize>
            </sensor>
          </link>
        </model>

        <joint name='camera_attachment' type='fixed'>
          <parent>Sentinel::iris_demo::iris::base_link</parent>
          <child>realsense_camera::link</child>
          <pose frame=''>0 0 0 0 -0 0</pose>
          <axis>
            <xyz>1 0 0</xyz>
            <use_parent_model_frame>0</use_parent_model_frame>
            <limit>
              <lower>-1.79769e+308</lower>
              <upper>1.79769e+308</upper>
              <effort>-1</effort>
              <velocity>-1</velocity>
            </limit>
            <dynamics>
              <spring_reference>0</spring_reference>
              <spring_stiffness>0</spring_stiffness>
              <damping>0</damping>
            </dynamics>
          </axis>
          <physics>
            <ode>
              <limit>
                <cfm>0</cfm>
                <erp>0.2</erp>
              </limit>
              <suspension>
                <cfm>0</cfm>
                <erp>0.2</erp>
              </suspension>
            </ode>
          </physics>
        </joint>
    </model>

    <gravity>0 0 -9.8</gravity>

    <magnetic_field>6e-06 2.3e-05 -4.2e-05</magnetic_field>

    <atmosphere type='adiabatic'/>

    <physics name='default_physics' default='0' type='ode'>
      <ode>
        <solver>
          <type>quick</type>
          <iters>100</iters>
          <sor>1.0</sor>
        </solver>
        <constraints>
          <cfm>0.0</cfm>
          <erp>0.9</erp>
          <contact_max_correcting_vel>0.1</contact_max_correcting_vel>
          <contact_surface_layer>0.0</contact_surface_layer>
        </constraints>
      </ode>
      <max_step_size>0.001</max_step_size>
      <real_time_factor>1</real_time_factor>
      <real_time_update_rate>0</real_time_update_rate>
    </physics>

    <scene>
      <ambient>0.4 0.4 0.4 1</ambient>
      <background>0.7 0.7 0.7 1</background>
      <shadows>0</shadows>
    </scene>

    <wind/>

    <spherical_coordinates>
      <surface_model>EARTH_WGS84</surface_model>
      <latitude_deg>0</latitude_deg>
      <longitude_deg>0</longitude_deg>
      <elevation>0</elevation>
      <heading_deg>0</heading_deg>
    </spherical_coordinates>

  </world>
</sdf>
